using System;
using System.Threading.Tasks;
using Xunit;
using Xunit.Sdk;
using Xunit.v3;

public class ExceptionAssertsTests
{
#pragma warning disable xUnit2015 // Do not use typeof expression to check the exception type

	public class Throws_NonGeneric
	{
		public class WithAction
		{
			[Fact]
			public static void GuardClauses()
			{
				static void testCode() { }

				Assert.Throws<ArgumentNullException>("exceptionType", () => Assert.Throws(null!, testCode));
				Assert.Throws<ArgumentNullException>("testCode", () => Assert.Throws(typeof(Exception), default(Action)!));
			}

			[Fact]
			public static void NoExceptionThrown()
			{
				static void testCode() { }

				var ex = Record.Exception(() => Assert.Throws(typeof(ArgumentException), testCode));

				Assert.IsType<ThrowsException>(ex);
				Assert.Equal(
					"Assert.Throws() Failure: No exception was thrown" + Environment.NewLine +
					"Expected: typeof(System.ArgumentException)",
					ex.Message
				);
				Assert.Null(ex.InnerException);
			}

			[Fact]
			public static void CorrectExceptionThrown()
			{
				static void testCode() => throw new ArgumentException();

				Assert.Throws(typeof(ArgumentException), testCode);
			}

			[Fact]
			public static void IncorrectExceptionThrown()
			{
				var thrown = new DivideByZeroException();
				void testCode() => throw thrown;

				var ex = Record.Exception(() => Assert.Throws(typeof(ArgumentException), testCode));

				Assert.IsType<ThrowsException>(ex);
				Assert.Equal(
					"Assert.Throws() Failure: Exception type was not an exact match" + Environment.NewLine +
					"Expected: typeof(System.ArgumentException)" + Environment.NewLine +
					"Actual:   typeof(System.DivideByZeroException)",
					ex.Message
				);
				Assert.Same(thrown, ex.InnerException);
			}

			[Fact]
			public static void DerivedExceptionThrown()
			{
				var thrown = new ArgumentNullException();
				void testCode() => throw thrown;

				var ex = Record.Exception(() => Assert.Throws(typeof(ArgumentException), testCode));

				Assert.IsType<ThrowsException>(ex);
				Assert.Equal(
					"Assert.Throws() Failure: Exception type was not an exact match" + Environment.NewLine +
					"Expected: typeof(System.ArgumentException)" + Environment.NewLine +
					"Actual:   typeof(System.ArgumentNullException)",
					ex.Message
				);
				Assert.Same(thrown, ex.InnerException);
			}

			[Fact]
			public static void SkipExceptionEscapes()
			{
				static void testCode() => Assert.Skip("This is a skipped test");

				try
				{
					Assert.Throws(typeof(Exception), testCode);
					Assert.Fail("The exception should not be caught");
				}
				catch (Exception ex)
				{
					Assert.Equal(DynamicSkipToken.Value + "This is a skipped test", ex.Message);
				}
			}
		}

		public class WithActionAndInspector
		{
			[Fact]
			public static void GuardClauses()
			{
				static void testCode() { }

				Assert.Throws<ArgumentNullException>("exceptionType", () => Assert.Throws(null!, testCode, _ => null));
				Assert.Throws<ArgumentNullException>("testCode", () => Assert.Throws(typeof(Exception), default(Action)!, _ => null));
			}

			[Fact]
			public static void NoExceptionThrown()
			{
				static void testCode() { }

				var ex = Record.Exception(() => Assert.Throws(typeof(ArgumentException), testCode, _ => null));

				Assert.IsType<ThrowsException>(ex);
				Assert.Equal(
					"Assert.Throws() Failure: No exception was thrown" + Environment.NewLine +
					"Expected: typeof(System.ArgumentException)",
					ex.Message
				);
				Assert.Null(ex.InnerException);
			}

			[Fact]
			public static void CorrectExceptionThrown_InspectorPasses()
			{
				static void testCode() => throw new ArgumentException();

				Assert.Throws(typeof(ArgumentException), testCode, _ => null);
			}

			[Fact]
			public static void CorrectExceptionThrown_InspectorFails()
			{
				static void testCode() => throw new ArgumentException();

				var ex = Record.Exception(() => Assert.Throws(typeof(ArgumentException), testCode, _ => "I don't like this exception"));

				Assert.IsType<ThrowsException>(ex);
				Assert.Equal("Assert.Throws() Failure: I don't like this exception", ex.Message);
				Assert.Null(ex.InnerException);
			}

			[Fact]
			public static void CorrectExceptionThrown_InspectorThrows()
			{
				static void testCode() => throw new ArgumentException();
				var thrownByInspector = new DivideByZeroException();

				var ex = Record.Exception(() => Assert.Throws(typeof(ArgumentException), testCode, _ => throw thrownByInspector));

				Assert.IsType<ThrowsException>(ex);
				Assert.StartsWith(
					"Assert.Throws() Failure: Exception thrown by inspector",
					ex.Message
				);
				Assert.Same(thrownByInspector, ex.InnerException);
			}

			[Fact]
			public static void IncorrectExceptionThrown()
			{
				var thrown = new DivideByZeroException();
				void testCode() => throw thrown;

				var ex = Record.Exception(() => Assert.Throws(typeof(ArgumentException), testCode, _ => null));

				Assert.IsType<ThrowsException>(ex);
				Assert.Equal(
					"Assert.Throws() Failure: Exception type was not an exact match" + Environment.NewLine +
					"Expected: typeof(System.ArgumentException)" + Environment.NewLine +
					"Actual:   typeof(System.DivideByZeroException)",
					ex.Message
				);
				Assert.Same(thrown, ex.InnerException);
			}

			[Fact]
			public static void DerivedExceptionThrown()
			{
				var thrown = new ArgumentNullException();
				void testCode() => throw thrown;

				var ex = Record.Exception(() => Assert.Throws(typeof(ArgumentException), testCode, _ => null));

				Assert.IsType<ThrowsException>(ex);
				Assert.Equal(
					"Assert.Throws() Failure: Exception type was not an exact match" + Environment.NewLine +
					"Expected: typeof(System.ArgumentException)" + Environment.NewLine +
					"Actual:   typeof(System.ArgumentNullException)",
					ex.Message
				);
				Assert.Same(thrown, ex.InnerException);
			}

			[Fact]
			public static void SkipExceptionEscapes()
			{
				static void testCode() => Assert.Skip("This is a skipped test");

				try
				{
					Assert.Throws(typeof(Exception), testCode, _ => null);
					Assert.Fail("The exception should not be caught");
				}
				catch (Exception ex)
				{
					Assert.Equal(DynamicSkipToken.Value + "This is a skipped test", ex.Message);
				}
			}
		}

		public class WithFunc
		{
			[Fact]
			public static void GuardClauses()
			{
				static object testCode() => 42;

				Assert.Throws<ArgumentNullException>("exceptionType", () => Assert.Throws(null!, testCode));
				Assert.Throws<ArgumentNullException>("testCode", () => Assert.Throws(typeof(Exception), default(Func<object>)!));
			}

			[Fact]
			public static void ProtectsAgainstAccidentalTask()
			{
				static object testCode() => Task.FromResult(42);

				var ex = Record.Exception(() => Assert.Throws(typeof(Exception), testCode));

				Assert.IsType<InvalidOperationException>(ex);
				Assert.Equal("You must call Assert.ThrowsAsync when testing async code", ex.Message);
			}

			[Fact]
			public static void NoExceptionThrown()
			{
				static object testCode() => 42;

				var ex = Record.Exception(() => Assert.Throws(typeof(ArgumentException), testCode));

				Assert.IsType<ThrowsException>(ex);
				Assert.Equal(
					"Assert.Throws() Failure: No exception was thrown" + Environment.NewLine +
					"Expected: typeof(System.ArgumentException)",
					ex.Message
				);
				Assert.Null(ex.InnerException);
			}

			[Fact]
			public static void CorrectExceptionThrown()
			{
				static object testCode() => throw new ArgumentException();

				Assert.Throws(typeof(ArgumentException), testCode);
			}

			[Fact]
			public static void IncorrectExceptionThrown()
			{
				var thrown = new DivideByZeroException();
				object testCode() => throw thrown;

				var ex = Record.Exception(() => Assert.Throws(typeof(ArgumentException), testCode));

				Assert.IsType<ThrowsException>(ex);
				Assert.Equal(
					"Assert.Throws() Failure: Exception type was not an exact match" + Environment.NewLine +
					"Expected: typeof(System.ArgumentException)" + Environment.NewLine +
					"Actual:   typeof(System.DivideByZeroException)",
					ex.Message
				);
				Assert.Same(thrown, ex.InnerException);
			}

			[Fact]
			public static void DerivedExceptionThrown()
			{
				var thrown = new ArgumentNullException();
				object testCode() => throw thrown;

				var ex = Record.Exception(() => Assert.Throws(typeof(ArgumentException), testCode));

				Assert.IsType<ThrowsException>(ex);
				Assert.Equal(
					"Assert.Throws() Failure: Exception type was not an exact match" + Environment.NewLine +
					"Expected: typeof(System.ArgumentException)" + Environment.NewLine +
					"Actual:   typeof(System.ArgumentNullException)",
					ex.Message
				);
				Assert.Same(thrown, ex.InnerException);
			}

			[Fact]
			public static void SkipExceptionEscapes()
			{
				static object testCode() { Assert.Skip("This is a skipped test"); return null; }

				try
				{
					Assert.Throws(typeof(Exception), testCode);
					Assert.Fail("The exception should not be caught");
				}
				catch (Exception ex)
				{
					Assert.Equal(DynamicSkipToken.Value + "This is a skipped test", ex.Message);
				}
			}
		}

		public class WithFuncAndInspector
		{
			[Fact]
			public static void GuardClauses()
			{
				static object testCode() => 42;

				Assert.Throws<ArgumentNullException>("exceptionType", () => Assert.Throws(null!, testCode, _ => null));
				Assert.Throws<ArgumentNullException>("testCode", () => Assert.Throws(typeof(Exception), default(Func<object>)!, _ => null));
			}

			[Fact]
			public static void ProtectsAgainstAccidentalTask()
			{
				static object testCode() => Task.FromResult(42);

				var ex = Record.Exception(() => Assert.Throws(typeof(Exception), testCode, _ => null));

				Assert.IsType<InvalidOperationException>(ex);
				Assert.Equal("You must call Assert.ThrowsAsync when testing async code", ex.Message);
			}

			[Fact]
			public static void NoExceptionThrown()
			{
				static object testCode() => 42;

				var ex = Record.Exception(() => Assert.Throws(typeof(ArgumentException), testCode, _ => null));

				Assert.IsType<ThrowsException>(ex);
				Assert.Equal(
					"Assert.Throws() Failure: No exception was thrown" + Environment.NewLine +
					"Expected: typeof(System.ArgumentException)",
					ex.Message
				);
				Assert.Null(ex.InnerException);
			}

			[Fact]
			public static void CorrectExceptionThrown_InspectorPasses()
			{
				static object testCode() => throw new ArgumentException();

				Assert.Throws(typeof(ArgumentException), testCode, _ => null);
			}

			[Fact]
			public static void CorrectExceptionThrown_InspectorFails()
			{
				static object testCode() => throw new ArgumentException();

				var ex = Record.Exception(() => Assert.Throws(typeof(ArgumentException), testCode, _ => "I don't like this exception"));

				Assert.IsType<ThrowsException>(ex);
				Assert.Equal("Assert.Throws() Failure: I don't like this exception", ex.Message);
				Assert.Null(ex.InnerException);
			}

			[Fact]
			public static void CorrectExceptionThrown_InspectorThrows()
			{
				static object testCode() => throw new ArgumentException();
				var thrownByInspector = new DivideByZeroException();

				var ex = Record.Exception(() => Assert.Throws(typeof(ArgumentException), testCode, _ => throw thrownByInspector));

				Assert.IsType<ThrowsException>(ex);
				Assert.StartsWith(
					"Assert.Throws() Failure: Exception thrown by inspector",
					ex.Message
				);
				Assert.Same(thrownByInspector, ex.InnerException);
			}

			[Fact]
			public static void IncorrectExceptionThrown()
			{
				var thrown = new DivideByZeroException();
				object testCode() => throw thrown;

				var ex = Record.Exception(() => Assert.Throws(typeof(ArgumentException), testCode, _ => null));

				Assert.IsType<ThrowsException>(ex);
				Assert.Equal(
					"Assert.Throws() Failure: Exception type was not an exact match" + Environment.NewLine +
					"Expected: typeof(System.ArgumentException)" + Environment.NewLine +
					"Actual:   typeof(System.DivideByZeroException)",
					ex.Message
				);
				Assert.Same(thrown, ex.InnerException);
			}

			[Fact]
			public static void DerivedExceptionThrown()
			{
				var thrown = new ArgumentNullException();
				object testCode() => throw thrown;

				var ex = Record.Exception(() => Assert.Throws(typeof(ArgumentException), testCode, _ => null));

				Assert.IsType<ThrowsException>(ex);
				Assert.Equal(
					"Assert.Throws() Failure: Exception type was not an exact match" + Environment.NewLine +
					"Expected: typeof(System.ArgumentException)" + Environment.NewLine +
					"Actual:   typeof(System.ArgumentNullException)",
					ex.Message
				);
				Assert.Same(thrown, ex.InnerException);
			}

			[Fact]
			public static void SkipExceptionEscapes()
			{
				static object testCode() { Assert.Skip("This is a skipped test"); return null; }

				try
				{
					Assert.Throws(typeof(Exception), testCode, _ => null);
					Assert.Fail("The exception should not be caught");
				}
				catch (Exception ex)
				{
					Assert.Equal(DynamicSkipToken.Value + "This is a skipped test", ex.Message);
				}
			}
		}
	}

#pragma warning restore xUnit2015 // Do not use typeof expression to check the exception type

	public class Throws_Generic
	{
		public class WithAction
		{
			[Fact]
			public static void GuardClause()
			{
				Assert.Throws<ArgumentNullException>("testCode", () => Assert.Throws<ArgumentException>(default(Action)!));
			}

			[Fact]
			public static void NoExceptionThrown()
			{
				static void testCode() { }

				var ex = Record.Exception(() => Assert.Throws<ArgumentException>(testCode));

				Assert.IsType<ThrowsException>(ex);
				Assert.Equal(
					"Assert.Throws() Failure: No exception was thrown" + Environment.NewLine +
					"Expected: typeof(System.ArgumentException)",
					ex.Message
				);
				Assert.Null(ex.InnerException);
			}

			[Fact]
			public static void CorrectExceptionThrown()
			{
				static void testCode() => throw new ArgumentException();

				Assert.Throws<ArgumentException>(testCode);
			}

			[Fact]
			public static void IncorrectExceptionThrown()
			{
				var thrown = new DivideByZeroException();
				void testCode() => throw thrown;

				var ex = Record.Exception(() => Assert.Throws<ArgumentException>(testCode));

				Assert.IsType<ThrowsException>(ex);
				Assert.Equal(
					"Assert.Throws() Failure: Exception type was not an exact match" + Environment.NewLine +
					"Expected: typeof(System.ArgumentException)" + Environment.NewLine +
					"Actual:   typeof(System.DivideByZeroException)",
					ex.Message
				);
				Assert.Same(thrown, ex.InnerException);
			}

			[Fact]
			public static void DerivedExceptionThrown()
			{
				var thrown = new ArgumentNullException();
				void testCode() => throw thrown;

				var ex = Record.Exception(() => Assert.Throws<ArgumentException>(testCode));

				Assert.IsType<ThrowsException>(ex);
				Assert.Equal(
					"Assert.Throws() Failure: Exception type was not an exact match" + Environment.NewLine +
					"Expected: typeof(System.ArgumentException)" + Environment.NewLine +
					"Actual:   typeof(System.ArgumentNullException)",
					ex.Message
				);
				Assert.Same(thrown, ex.InnerException);
			}

			[Fact]
			public static void SkipExceptionEscapes()
			{
				static void testCode() => Assert.Skip("This is a skipped test");

				try
				{
					Assert.Throws<Exception>(testCode);
					Assert.Fail("The exception should not be caught");
				}
				catch (Exception ex)
				{
					Assert.Equal(DynamicSkipToken.Value + "This is a skipped test", ex.Message);
				}
			}
		}

		public class WithActionAndInspector
		{
			[Fact]
			public static void GuardClause()
			{
				Assert.Throws<ArgumentNullException>("testCode", () => Assert.Throws<ArgumentException>(default(Action)!, _ => null));
			}

			[Fact]
			public static void NoExceptionThrown()
			{
				static void testCode() { }

				var ex = Record.Exception(() => Assert.Throws<ArgumentException>(testCode, _ => null));

				Assert.IsType<ThrowsException>(ex);
				Assert.Equal(
					"Assert.Throws() Failure: No exception was thrown" + Environment.NewLine +
					"Expected: typeof(System.ArgumentException)",
					ex.Message
				);
				Assert.Null(ex.InnerException);
			}

			[Fact]
			public static void CorrectExceptionThrown_InspectorPasses()
			{
				static void testCode() => throw new ArgumentException();

				Assert.Throws<ArgumentException>(testCode, _ => null);
			}

			[Fact]
			public static void CorrectExceptionThrown_InspectorFails()
			{
				static void testCode() => throw new ArgumentException();

				var ex = Record.Exception(() => Assert.Throws<ArgumentException>(testCode, _ => "I don't like this exception"));

				Assert.IsType<ThrowsException>(ex);
				Assert.Equal("Assert.Throws() Failure: I don't like this exception", ex.Message); Assert.Null(ex.InnerException);
			}

			[Fact]
			public static void CorrectExceptionThrown_InspectorThrows()
			{
				static void testCode() => throw new ArgumentException();
				var thrownByInspector = new DivideByZeroException();

				var ex = Record.Exception(() => Assert.Throws<ArgumentException>(testCode, _ => throw thrownByInspector));

				Assert.IsType<ThrowsException>(ex);
				Assert.Equal(
					"Assert.Throws() Failure: Exception thrown by inspector",
					ex.Message
				);
				Assert.Same(thrownByInspector, ex.InnerException);
			}

			[Fact]
			public static void IncorrectExceptionThrown()
			{
				var thrown = new DivideByZeroException();
				void testCode() => throw thrown;

				var ex = Record.Exception(() => Assert.Throws<ArgumentException>(testCode, _ => null));

				Assert.IsType<ThrowsException>(ex);
				Assert.Equal(
					"Assert.Throws() Failure: Exception type was not an exact match" + Environment.NewLine +
					"Expected: typeof(System.ArgumentException)" + Environment.NewLine +
					"Actual:   typeof(System.DivideByZeroException)",
					ex.Message
				);
				Assert.Same(thrown, ex.InnerException);
			}

			[Fact]
			public static void DerivedExceptionThrown()
			{
				var thrown = new ArgumentNullException();
				void testCode() => throw thrown;

				var ex = Record.Exception(() => Assert.Throws<ArgumentException>(testCode, _ => null));

				Assert.IsType<ThrowsException>(ex);
				Assert.Equal(
					"Assert.Throws() Failure: Exception type was not an exact match" + Environment.NewLine +
					"Expected: typeof(System.ArgumentException)" + Environment.NewLine +
					"Actual:   typeof(System.ArgumentNullException)",
					ex.Message
				);
				Assert.Same(thrown, ex.InnerException);
			}

			[Fact]
			public static void SkipExceptionEscapes()
			{
				static void testCode() => Assert.Skip("This is a skipped test");

				try
				{
					Assert.Throws<Exception>(testCode, _ => null);
					Assert.Fail("The exception should not be caught");
				}
				catch (Exception ex)
				{
					Assert.Equal(DynamicSkipToken.Value + "This is a skipped test", ex.Message);
				}
			}
		}

		public class WithFunc
		{
			[Fact]
			public static void GuardClause()
			{
				Assert.Throws<ArgumentNullException>("testCode", () => Assert.Throws<ArgumentException>(default(Func<object>)!));
			}

			[Fact]
			public static void ProtectsAgainstAccidentalTask()
			{
				static object testCode() => Task.FromResult(42);

				var ex = Record.Exception(() => Assert.Throws<Exception>(testCode));

				Assert.IsType<InvalidOperationException>(ex);
				Assert.Equal("You must call Assert.ThrowsAsync when testing async code", ex.Message);
			}

			[Fact]
			public static void NoExceptionThrown()
			{
				static object testCode() => 42;

				var ex = Record.Exception(() => Assert.Throws<ArgumentException>(testCode));

				Assert.IsType<ThrowsException>(ex);
				Assert.Equal(
					"Assert.Throws() Failure: No exception was thrown" + Environment.NewLine +
					"Expected: typeof(System.ArgumentException)",
					ex.Message
				);
				Assert.Null(ex.InnerException);
			}

			[Fact]
			public static void CorrectExceptionThrown()
			{
				static object testCode() => throw new ArgumentException();

				Assert.Throws<ArgumentException>(testCode);
			}

			[Fact]
			public static void IncorrectExceptionThrown()
			{
				var thrown = new DivideByZeroException();
				object testCode() => throw thrown;

				var ex = Record.Exception(() => Assert.Throws<ArgumentException>(testCode));

				Assert.IsType<ThrowsException>(ex);
				Assert.Equal(
					"Assert.Throws() Failure: Exception type was not an exact match" + Environment.NewLine +
					"Expected: typeof(System.ArgumentException)" + Environment.NewLine +
					"Actual:   typeof(System.DivideByZeroException)",
					ex.Message
				);
				Assert.Same(thrown, ex.InnerException);
			}

			[Fact]
			public static void DerivedExceptionThrown()
			{
				var thrown = new ArgumentNullException();
				object testCode() => throw thrown;

				var ex = Record.Exception(() => Assert.Throws<ArgumentException>(testCode));

				Assert.IsType<ThrowsException>(ex);
				Assert.Equal(
					"Assert.Throws() Failure: Exception type was not an exact match" + Environment.NewLine +
					"Expected: typeof(System.ArgumentException)" + Environment.NewLine +
					"Actual:   typeof(System.ArgumentNullException)",
					ex.Message
				);
				Assert.Same(thrown, ex.InnerException);
			}

			[Fact]
			public static void SkipExceptionEscapes()
			{
				static object testCode() { Assert.Skip("This is a skipped test"); return null; }

				try
				{
					Assert.Throws<Exception>(testCode);
					Assert.Fail("The exception should not be caught");
				}
				catch (Exception ex)
				{
					Assert.Equal(DynamicSkipToken.Value + "This is a skipped test", ex.Message);
				}
			}
		}

		public class WithFuncAndInspector
		{
			[Fact]
			public static void GuardClause()
			{
				Assert.Throws<ArgumentNullException>("testCode", () => Assert.Throws<ArgumentException>(default(Func<object>)!, _ => null));
			}

			[Fact]
			public static void ProtectsAgainstAccidentalTask()
			{
				static object testCode() => Task.FromResult(42);

				var ex = Record.Exception(() => Assert.Throws<Exception>(testCode, _ => null));

				Assert.IsType<InvalidOperationException>(ex);
				Assert.Equal("You must call Assert.ThrowsAsync when testing async code", ex.Message);
			}

			[Fact]
			public static void NoExceptionThrown()
			{
				static object testCode() => 42;

				var ex = Record.Exception(() => Assert.Throws<ArgumentException>(testCode, _ => null));

				Assert.IsType<ThrowsException>(ex);
				Assert.Equal(
					"Assert.Throws() Failure: No exception was thrown" + Environment.NewLine +
					"Expected: typeof(System.ArgumentException)",
					ex.Message
				);
				Assert.Null(ex.InnerException);
			}

			[Fact]
			public static void CorrectExceptionThrown_InspectorPasses()
			{
				static object testCode() => throw new ArgumentException();

				Assert.Throws<ArgumentException>(testCode, _ => null);
			}

			[Fact]
			public static void CorrectExceptionThrown_InspectorFailed()
			{
				static object testCode() => throw new ArgumentException();

				var ex = Record.Exception(() => Assert.Throws<ArgumentException>(testCode, _ => "I don't like this exception"));

				Assert.IsType<ThrowsException>(ex);
				Assert.Equal("Assert.Throws() Failure: I don't like this exception", ex.Message);
				Assert.Null(ex.InnerException);
			}

			[Fact]
			public static void CorrectExceptionThrown_InspectorThrows()
			{
				static object testCode() => throw new ArgumentException();
				var thrownByInspector = new DivideByZeroException();

				var ex = Record.Exception(() => Assert.Throws<ArgumentException>(testCode, _ => throw thrownByInspector));

				Assert.IsType<ThrowsException>(ex);
				Assert.Equal("Assert.Throws() Failure: Exception thrown by inspector", ex.Message);
				Assert.Same(thrownByInspector, ex.InnerException);
			}

			[Fact]
			public static void IncorrectExceptionThrown()
			{
				var thrown = new DivideByZeroException();
				object testCode() => throw thrown;

				var ex = Record.Exception(() => Assert.Throws<ArgumentException>(testCode, _ => null));

				Assert.IsType<ThrowsException>(ex);
				Assert.Equal(
					"Assert.Throws() Failure: Exception type was not an exact match" + Environment.NewLine +
					"Expected: typeof(System.ArgumentException)" + Environment.NewLine +
					"Actual:   typeof(System.DivideByZeroException)",
					ex.Message
				);
				Assert.Same(thrown, ex.InnerException);
			}

			[Fact]
			public static void DerivedExceptionThrown()
			{
				var thrown = new ArgumentNullException();
				object testCode() => throw thrown;

				var ex = Record.Exception(() => Assert.Throws<ArgumentException>(testCode, _ => null));

				Assert.IsType<ThrowsException>(ex);
				Assert.Equal(
					"Assert.Throws() Failure: Exception type was not an exact match" + Environment.NewLine +
					"Expected: typeof(System.ArgumentException)" + Environment.NewLine +
					"Actual:   typeof(System.ArgumentNullException)",
					ex.Message
				);
				Assert.Same(thrown, ex.InnerException);
			}

			[Fact]
			public static void SkipExceptionEscapes()
			{
				static object testCode() { Assert.Skip("This is a skipped test"); return null; }

				try
				{
					Assert.Throws<Exception>(testCode, _ => null);
					Assert.Fail("The exception should not be caught");
				}
				catch (Exception ex)
				{
					Assert.Equal(DynamicSkipToken.Value + "This is a skipped test", ex.Message);
				}
			}
		}
	}

	public class Throws_Generic_ArgumentException
	{
		public class WithAction
		{
			[Fact]
			public static void GuardClause()
			{
				Assert.Throws<ArgumentNullException>("testCode", () => Assert.Throws<ArgumentException>(default(Action)!));
			}

			[Fact]
			public static void NoExceptionThrown()
			{
				static void testCode() { }

				var ex = Record.Exception(() => Assert.Throws<ArgumentException>("paramName", testCode));

				Assert.IsType<ThrowsException>(ex);
				Assert.Equal(
					"Assert.Throws() Failure: No exception was thrown" + Environment.NewLine +
					"Expected: typeof(System.ArgumentException)",
					ex.Message
				);
				Assert.Null(ex.InnerException);
			}

			[Fact]
			public static void CorrectExceptionThrown()
			{
				static void testCode() => throw new ArgumentException("Hello world", "paramName");

				Assert.Throws<ArgumentException>("paramName", testCode);
			}

			[Fact]
			public static void IncorrectParameterName()
			{
				static void testCode() => throw new ArgumentException("Hello world", "paramName1");

				var ex = Record.Exception(() => Assert.Throws<ArgumentException>("paramName2", testCode));

				Assert.IsType<ThrowsException>(ex);
				Assert.Equal(
					"Assert.Throws() Failure: Incorrect parameter name" + Environment.NewLine +
					"Exception: typeof(System.ArgumentException)" + Environment.NewLine +
					"Expected:  \"paramName2\"" + Environment.NewLine +
					"Actual:    \"paramName1\"",
					ex.Message
				);
			}

			[Fact]
			public static void IncorrectExceptionThrown()
			{
				var thrown = new DivideByZeroException();
				void testCode() => throw thrown;

				var ex = Record.Exception(() => Assert.Throws<ArgumentException>("paramName", testCode));

				Assert.IsType<ThrowsException>(ex);
				Assert.Equal(
					"Assert.Throws() Failure: Exception type was not an exact match" + Environment.NewLine +
					"Expected: typeof(System.ArgumentException)" + Environment.NewLine +
					"Actual:   typeof(System.DivideByZeroException)",
					ex.Message
				);
				Assert.Same(thrown, ex.InnerException);
			}

			[Fact]
			public static void DerivedExceptionThrown()
			{
				var thrown = new ArgumentNullException();
				void testCode() => throw thrown;

				var ex = Record.Exception(() => Assert.Throws<ArgumentException>("paramName", testCode));

				Assert.IsType<ThrowsException>(ex);
				Assert.Equal(
					"Assert.Throws() Failure: Exception type was not an exact match" + Environment.NewLine +
					"Expected: typeof(System.ArgumentException)" + Environment.NewLine +
					"Actual:   typeof(System.ArgumentNullException)",
					ex.Message
				);
				Assert.Same(thrown, ex.InnerException);
			}
		}

		public class WithFunc
		{
			[Fact]
			public static void GuardClause()
			{
				Assert.Throws<ArgumentNullException>("testCode", () => Assert.Throws<ArgumentException>(default(Func<object>)!));
			}

			[Fact]
			public static void NoExceptionThrown()
			{
				static object testCode() => 42;

				var ex = Record.Exception(() => Assert.Throws<ArgumentException>("paramName", testCode));

				Assert.IsType<ThrowsException>(ex);
				Assert.Equal(
					"Assert.Throws() Failure: No exception was thrown" + Environment.NewLine +
					"Expected: typeof(System.ArgumentException)",
					ex.Message
				);
				Assert.Null(ex.InnerException);
			}

			[Fact]
			public static void CorrectExceptionThrown()
			{
				static object testCode() => throw new ArgumentException("Hello world", "paramName");

				Assert.Throws<ArgumentException>("paramName", testCode);
			}

			[Fact]
			public static void IncorrectParameterName()
			{
				static object testCode() => throw new ArgumentException("Hello world", "paramName1");

				var ex = Record.Exception(() => Assert.Throws<ArgumentException>("paramName2", testCode));

				Assert.IsType<ThrowsException>(ex);
				Assert.Equal(
					"Assert.Throws() Failure: Incorrect parameter name" + Environment.NewLine +
					"Exception: typeof(System.ArgumentException)" + Environment.NewLine +
					"Expected:  \"paramName2\"" + Environment.NewLine +
					"Actual:    \"paramName1\"",
					ex.Message
				);
			}

			[Fact]
			public static void IncorrectExceptionThrown()
			{
				var thrown = new DivideByZeroException();
				object testCode() => throw thrown;

				var ex = Record.Exception(() => Assert.Throws<ArgumentException>("paramName", testCode));

				Assert.IsType<ThrowsException>(ex);
				Assert.Equal(
					"Assert.Throws() Failure: Exception type was not an exact match" + Environment.NewLine +
					"Expected: typeof(System.ArgumentException)" + Environment.NewLine +
					"Actual:   typeof(System.DivideByZeroException)",
					ex.Message
				);
				Assert.Same(thrown, ex.InnerException);
			}

			[Fact]
			public static void DerivedExceptionThrown()
			{
				var thrown = new ArgumentNullException();
				object testCode() => throw thrown;

				var ex = Record.Exception(() => Assert.Throws<ArgumentException>("paramName", testCode));

				Assert.IsType<ThrowsException>(ex);
				Assert.Equal(
					"Assert.Throws() Failure: Exception type was not an exact match" + Environment.NewLine +
					"Expected: typeof(System.ArgumentException)" + Environment.NewLine +
					"Actual:   typeof(System.ArgumentNullException)",
					ex.Message
				);
				Assert.Same(thrown, ex.InnerException);
			}
		}
	}

	public class ThrowsAny
	{
		public class WithAction
		{
			[Fact]
			public static void GuardClause()
			{
				Assert.Throws<ArgumentNullException>("testCode", () => Assert.ThrowsAny<ArgumentException>(default(Action)!));
			}

			[Fact]
			public static void NoExceptionThrown()
			{
				static void testCode() { }

				var ex = Record.Exception(() => Assert.ThrowsAny<ArgumentException>(testCode));

				Assert.IsType<ThrowsAnyException>(ex);
				Assert.Equal(
					"Assert.ThrowsAny() Failure: No exception was thrown" + Environment.NewLine +
					"Expected: typeof(System.ArgumentException)",
					ex.Message
				);
				Assert.Null(ex.InnerException);
			}

			[Fact]
			public static void CorrectExceptionThrown()
			{
				static void testCode() => throw new ArgumentException();

				Assert.ThrowsAny<ArgumentException>(testCode);
			}

			[Fact]
			public static void IncorrectExceptionThrown()
			{
				var thrown = new DivideByZeroException();
				void testCode() => throw thrown;

				var ex = Record.Exception(() => Assert.ThrowsAny<ArgumentException>(testCode));

				Assert.IsType<ThrowsAnyException>(ex);
				Assert.Equal(
					"Assert.ThrowsAny() Failure: Exception type was not compatible" + Environment.NewLine +
					"Expected: typeof(System.ArgumentException)" + Environment.NewLine +
					"Actual:   typeof(System.DivideByZeroException)",
					ex.Message
				);
				Assert.Same(thrown, ex.InnerException);
			}

			[Fact]
			public static void DerivedExceptionThrown()
			{
				static void testCode() => throw new ArgumentNullException();

				Assert.ThrowsAny<ArgumentException>(testCode);
			}

			[Fact]
			public static void SkipExceptionEscapes()
			{
				static void testCode() => Assert.Skip("This is a skipped test");

				try
				{
					Assert.ThrowsAny<Exception>(testCode);
					Assert.Fail("The exception should not be caught");
				}
				catch (Exception ex)
				{
					Assert.Equal(DynamicSkipToken.Value + "This is a skipped test", ex.Message);
				}
			}
		}

		public class WithActionAndInspector
		{
			[Fact]
			public static void GuardClause()
			{
				Assert.Throws<ArgumentNullException>("testCode", () => Assert.ThrowsAny<ArgumentException>(default(Action)!, _ => null));
			}

			[Fact]
			public static void NoExceptionThrown()
			{
				static void testCode() { }

				var ex = Record.Exception(() => Assert.ThrowsAny<ArgumentException>(testCode, _ => null));

				Assert.IsType<ThrowsAnyException>(ex);
				Assert.Equal(
					"Assert.ThrowsAny() Failure: No exception was thrown" + Environment.NewLine +
					"Expected: typeof(System.ArgumentException)",
					ex.Message
				);
				Assert.Null(ex.InnerException);
			}

			[Fact]
			public static void CorrectExceptionThrown_InspectorPasses()
			{
				static void testCode() => throw new ArgumentException();

				Assert.ThrowsAny<ArgumentException>(testCode, _ => null);
			}

			[Fact]
			public static void CorrectExceptionThrown_InspectorFails()
			{
				static void testCode() => throw new ArgumentException();

				var ex = Record.Exception(() => Assert.ThrowsAny<ArgumentException>(testCode, _ => "I don't like this exception"));

				Assert.IsType<ThrowsAnyException>(ex);
				Assert.Equal("Assert.ThrowsAny() Failure: I don't like this exception", ex.Message);
				Assert.Null(ex.InnerException);
			}

			[Fact]
			public static void CorrectExceptionThrown_InspectorThrows()
			{
				static void testCode() => throw new ArgumentException();
				var thrownByInspector = new DivideByZeroException();

				var ex = Record.Exception(() => Assert.ThrowsAny<ArgumentException>(testCode, _ => throw thrownByInspector));

				Assert.IsType<ThrowsAnyException>(ex);
				Assert.Equal("Assert.ThrowsAny() Failure: Exception thrown by inspector", ex.Message);
				Assert.Same(thrownByInspector, ex.InnerException);
			}

			[Fact]
			public static void IncorrectExceptionThrown()
			{
				var thrown = new DivideByZeroException();
				void testCode() => throw thrown;

				var ex = Record.Exception(() => Assert.ThrowsAny<ArgumentException>(testCode, _ => null));

				Assert.IsType<ThrowsAnyException>(ex);
				Assert.Equal(
					"Assert.ThrowsAny() Failure: Exception type was not compatible" + Environment.NewLine +
					"Expected: typeof(System.ArgumentException)" + Environment.NewLine +
					"Actual:   typeof(System.DivideByZeroException)",
					ex.Message
				);
				Assert.Same(thrown, ex.InnerException);
			}

			[Fact]
			public static void DerivedExceptionThrown_InspectorPasses()
			{
				static void testCode() => throw new ArgumentNullException();

				Assert.ThrowsAny<ArgumentException>(testCode, _ => null);
			}

			[Fact]
			public static void DerivedExceptionThrown_InspectorFails()
			{
				static void testCode() => throw new ArgumentNullException();

				var ex = Record.Exception(() => Assert.ThrowsAny<ArgumentException>(testCode, _ => "I don't like this exception"));

				Assert.IsType<ThrowsAnyException>(ex);
				Assert.Equal("Assert.ThrowsAny() Failure: I don't like this exception", ex.Message);
				Assert.Null(ex.InnerException);
			}

			[Fact]
			public static void DerivedExceptionThrown_InspectorThrows()
			{
				static void testCode() => throw new ArgumentNullException();
				var thrownByInspector = new DivideByZeroException();

				var ex = Record.Exception(() => Assert.ThrowsAny<ArgumentException>(testCode, _ => throw thrownByInspector));

				Assert.IsType<ThrowsAnyException>(ex);
				Assert.Equal("Assert.ThrowsAny() Failure: Exception thrown by inspector", ex.Message);
				Assert.Same(thrownByInspector, ex.InnerException);
			}

			[Fact]
			public static void SkipExceptionEscapes()
			{
				static void testCode() => Assert.Skip("This is a skipped test");

				try
				{
					Assert.ThrowsAny<Exception>(testCode, _ => null);
					Assert.Fail("The exception should not be caught");
				}
				catch (Exception ex)
				{
					Assert.Equal(DynamicSkipToken.Value + "This is a skipped test", ex.Message);
				}
			}
		}

		public class WithFunc
		{
			[Fact]
			public static void GuardClause()
			{
				Assert.Throws<ArgumentNullException>("testCode", () => Assert.ThrowsAny<ArgumentException>(default(Func<object>)!));
			}

			[Fact]
			public static void ProtectsAgainstAccidentalTask()
			{
				static object testCode() => Task.FromResult(42);

				var ex = Record.Exception(() => Assert.ThrowsAny<Exception>(testCode));

				Assert.IsType<InvalidOperationException>(ex);
				Assert.Equal("You must call Assert.ThrowsAnyAsync when testing async code", ex.Message);
			}

			[Fact]
			public static void NoExceptionThrown()
			{
				static object testCode() => 42;

				var ex = Record.Exception(() => Assert.ThrowsAny<ArgumentException>(testCode));

				Assert.IsType<ThrowsAnyException>(ex);
				Assert.Equal(
					"Assert.ThrowsAny() Failure: No exception was thrown" + Environment.NewLine +
					"Expected: typeof(System.ArgumentException)",
					ex.Message
				);
				Assert.Null(ex.InnerException);
			}

			[Fact]
			public static void CorrectExceptionThrown()
			{
				static object testCode() => throw new ArgumentException();

				Assert.ThrowsAny<ArgumentException>(testCode);
			}

			[Fact]
			public static void IncorrectExceptionThrown()
			{
				var thrown = new DivideByZeroException();
				object testCode() => throw thrown;

				var ex = Record.Exception(() => Assert.ThrowsAny<ArgumentException>(testCode));

				Assert.IsType<ThrowsAnyException>(ex);
				Assert.Equal(
					"Assert.ThrowsAny() Failure: Exception type was not compatible" + Environment.NewLine +
					"Expected: typeof(System.ArgumentException)" + Environment.NewLine +
					"Actual:   typeof(System.DivideByZeroException)",
					ex.Message
				);
				Assert.Same(thrown, ex.InnerException);
			}

			[Fact]
			public static void DerivedExceptionThrown()
			{
				static object testCode() => throw new ArgumentNullException();

				Assert.ThrowsAny<ArgumentException>(testCode);
			}

			[Fact]
			public static void SkipExceptionEscapes()
			{
				static object testCode() { Assert.Skip("This is a skipped test"); return null; }

				try
				{
					Assert.ThrowsAny<Exception>(testCode);
					Assert.Fail("The exception should not be caught");
				}
				catch (Exception ex)
				{
					Assert.Equal(DynamicSkipToken.Value + "This is a skipped test", ex.Message);
				}
			}
		}

		public class WithFuncAndInspector
		{
			[Fact]
			public static void GuardClause()
			{
				Assert.Throws<ArgumentNullException>("testCode", () => Assert.ThrowsAny<ArgumentException>(default(Func<object>)!, _ => null));
			}

			[Fact]
			public static void ProtectsAgainstAccidentalTask()
			{
				static object testCode() => Task.FromResult(42);

				var ex = Record.Exception(() => Assert.ThrowsAny<Exception>(testCode, _ => null));

				Assert.IsType<InvalidOperationException>(ex);
				Assert.Equal("You must call Assert.ThrowsAnyAsync when testing async code", ex.Message);
			}

			[Fact]
			public static void NoExceptionThrown()
			{
				static object testCode() => 42;

				var ex = Record.Exception(() => Assert.ThrowsAny<ArgumentException>(testCode, _ => null));

				Assert.IsType<ThrowsAnyException>(ex);
				Assert.Equal(
					"Assert.ThrowsAny() Failure: No exception was thrown" + Environment.NewLine +
					"Expected: typeof(System.ArgumentException)",
					ex.Message
				);
				Assert.Null(ex.InnerException);
			}

			[Fact]
			public static void CorrectExceptionThrown_InspectorPasses()
			{
				static object testCode() => throw new ArgumentException();

				Assert.ThrowsAny<ArgumentException>(testCode, _ => null);
			}

			[Fact]
			public static void CorrectExceptionThrown_InspectorFails()
			{
				static object testCode() => throw new ArgumentException();

				var ex = Record.Exception(() => Assert.ThrowsAny<ArgumentException>(testCode, _ => "I don't like this exception"));

				Assert.IsType<ThrowsAnyException>(ex);
				Assert.Equal("Assert.ThrowsAny() Failure: I don't like this exception", ex.Message);
				Assert.Null(ex.InnerException);
			}

			[Fact]
			public static void CorrectExceptionThrown_InspectorThrows()
			{
				static object testCode() => throw new ArgumentException();
				var thrownByInspector = new DivideByZeroException();

				var ex = Record.Exception(() => Assert.ThrowsAny<ArgumentException>(testCode, _ => throw thrownByInspector));

				Assert.IsType<ThrowsAnyException>(ex);
				Assert.Equal("Assert.ThrowsAny() Failure: Exception thrown by inspector", ex.Message);
				Assert.Same(thrownByInspector, ex.InnerException);
			}

			[Fact]
			public static void IncorrectExceptionThrown()
			{
				var thrown = new DivideByZeroException();
				object testCode() => throw thrown;

				var ex = Record.Exception(() => Assert.ThrowsAny<ArgumentException>(testCode, _ => null));

				Assert.IsType<ThrowsAnyException>(ex);
				Assert.Equal(
					"Assert.ThrowsAny() Failure: Exception type was not compatible" + Environment.NewLine +
					"Expected: typeof(System.ArgumentException)" + Environment.NewLine +
					"Actual:   typeof(System.DivideByZeroException)",
					ex.Message
				);
				Assert.Same(thrown, ex.InnerException);
			}

			[Fact]
			public static void DerivedExceptionThrown_InspectorPasses()
			{
				static object testCode() => throw new ArgumentNullException();

				Assert.ThrowsAny<ArgumentException>(testCode, _ => null);
			}

			[Fact]
			public static void DerivedExceptionThrown_InspectorFails()
			{
				static object testCode() => throw new ArgumentNullException();

				var ex = Record.Exception(() => Assert.ThrowsAny<ArgumentException>(testCode, _ => "I don't like this exception"));

				Assert.IsType<ThrowsAnyException>(ex);
				Assert.Equal("Assert.ThrowsAny() Failure: I don't like this exception", ex.Message);
				Assert.Null(ex.InnerException);
			}

			[Fact]
			public static void DerivedExceptionThrown_InspectorThrows()
			{
				static object testCode() => throw new ArgumentNullException();
				var thrownByInspector = new DivideByZeroException();

				var ex = Record.Exception(() => Assert.ThrowsAny<ArgumentException>(testCode, _ => throw thrownByInspector));

				Assert.IsType<ThrowsAnyException>(ex);
				Assert.Equal("Assert.ThrowsAny() Failure: Exception thrown by inspector", ex.Message);
				Assert.Same(thrownByInspector, ex.InnerException);
			}

			[Fact]
			public static void SkipExceptionEscapes()
			{
				static object testCode() { Assert.Skip("This is a skipped test"); return null; }

				try
				{
					Assert.ThrowsAny<Exception>(testCode, _ => null);
					Assert.Fail("The exception should not be caught");
				}
				catch (Exception ex)
				{
					Assert.Equal(DynamicSkipToken.Value + "This is a skipped test", ex.Message);
				}
			}
		}
	}

	public class ThrowsAnyAsync
	{
		public class WithoutInspector
		{
			[Fact]
			public static async Task GuardClause()
			{
				await Assert.ThrowsAsync<ArgumentNullException>("testCode", () => Assert.ThrowsAnyAsync<ArgumentException>(default!));
			}

			[Fact]
			public static async Task NoExceptionThrown()
			{
				static Task testCode() => Task.FromResult(42);

				var ex = await Record.ExceptionAsync(() => Assert.ThrowsAnyAsync<ArgumentException>(testCode));

				Assert.IsType<ThrowsAnyException>(ex);
				Assert.Equal(
					"Assert.ThrowsAny() Failure: No exception was thrown" + Environment.NewLine +
					"Expected: typeof(System.ArgumentException)",
					ex.Message
				);
				Assert.Null(ex.InnerException);
			}

			[Fact]
			public static async Task CorrectExceptionThrown()
			{
				static Task testCode() => throw new ArgumentException();

				await Assert.ThrowsAnyAsync<ArgumentException>(testCode);
			}

			[Fact]
			public static async Task IncorrectExceptionThrown()
			{
				var thrown = new DivideByZeroException();
				Task testCode() => throw thrown;

				var ex = await Record.ExceptionAsync(() => Assert.ThrowsAnyAsync<ArgumentException>(testCode));

				Assert.IsType<ThrowsAnyException>(ex);
				Assert.Equal(
					"Assert.ThrowsAny() Failure: Exception type was not compatible" + Environment.NewLine +
					"Expected: typeof(System.ArgumentException)" + Environment.NewLine +
					"Actual:   typeof(System.DivideByZeroException)",
					ex.Message
				);
				Assert.Same(thrown, ex.InnerException);
			}

			[Fact]
			public static async Task DerivedExceptionThrown()
			{
				static Task testCode() => throw new ArgumentNullException();

				await Assert.ThrowsAnyAsync<ArgumentException>(testCode);
			}

			[Fact]
			public static async Task SkipExceptionEscapes()
			{
				static Task testCode() { Assert.Skip("This is a skipped test"); return Task.CompletedTask; }

				try
				{
					await Assert.ThrowsAnyAsync<Exception>(testCode);
					Assert.Fail("The exception should not be caught");
				}
				catch (Exception ex)
				{
					Assert.Equal(DynamicSkipToken.Value + "This is a skipped test", ex.Message);
				}
			}
		}

		public class WithInspector
		{
			[Fact]
			public static async Task GuardClause()
			{
				await Assert.ThrowsAsync<ArgumentNullException>("testCode", () => Assert.ThrowsAnyAsync<ArgumentException>(default!, _ => null));
			}

			[Fact]
			public static async Task NoExceptionThrown()
			{
				static Task testCode() => Task.FromResult(42);

				var ex = await Record.ExceptionAsync(() => Assert.ThrowsAnyAsync<ArgumentException>(testCode, _ => null));

				Assert.IsType<ThrowsAnyException>(ex);
				Assert.Equal(
					"Assert.ThrowsAny() Failure: No exception was thrown" + Environment.NewLine +
					"Expected: typeof(System.ArgumentException)",
					ex.Message
				);
				Assert.Null(ex.InnerException);
			}

			[Fact]
			public static async Task CorrectExceptionThrown_InspectorPasses()
			{
				static Task testCode() => throw new ArgumentException();

				await Assert.ThrowsAnyAsync<ArgumentException>(testCode, _ => null);
			}

			[Fact]
			public static async Task CorrectExceptionThrown_InspectorFails()
			{
				static Task testCode() => throw new ArgumentException();

				var ex = await Record.ExceptionAsync(() => Assert.ThrowsAnyAsync<ArgumentException>(testCode, _ => "I don't like this exception"));

				Assert.IsType<ThrowsAnyException>(ex);
				Assert.Equal("Assert.ThrowsAny() Failure: I don't like this exception", ex.Message);
				Assert.Null(ex.InnerException);
			}

			[Fact]
			public static async Task CorrectExceptionThrown_InspectorThrows()
			{
				static Task testCode() => throw new ArgumentException();
				var thrownByInspector = new DivideByZeroException();

				var ex = await Record.ExceptionAsync(() => Assert.ThrowsAnyAsync<ArgumentException>(testCode, _ => throw thrownByInspector));

				Assert.IsType<ThrowsAnyException>(ex);
				Assert.Equal("Assert.ThrowsAny() Failure: Exception thrown by inspector", ex.Message);
				Assert.Same(thrownByInspector, ex.InnerException);
			}

			[Fact]
			public static async Task IncorrectExceptionThrown()
			{
				var thrown = new DivideByZeroException();
				Task testCode() => throw thrown;

				var ex = await Record.ExceptionAsync(() => Assert.ThrowsAnyAsync<ArgumentException>(testCode, _ => null));

				Assert.IsType<ThrowsAnyException>(ex);
				Assert.Equal(
					"Assert.ThrowsAny() Failure: Exception type was not compatible" + Environment.NewLine +
					"Expected: typeof(System.ArgumentException)" + Environment.NewLine +
					"Actual:   typeof(System.DivideByZeroException)",
					ex.Message
				);
				Assert.Same(thrown, ex.InnerException);
			}

			[Fact]
			public static async Task DerivedExceptionThrown_InspectorPasses()
			{
				static Task testCode() => throw new ArgumentNullException();

				await Assert.ThrowsAnyAsync<ArgumentException>(testCode, _ => null);
			}

			[Fact]
			public static async Task DerivedExceptionThrown_InspectorFails()
			{
				static Task testCode() => throw new ArgumentNullException();

				var ex = await Record.ExceptionAsync(() => Assert.ThrowsAnyAsync<ArgumentException>(testCode, _ => "I don't like this exception"));

				Assert.IsType<ThrowsAnyException>(ex);
				Assert.Equal("Assert.ThrowsAny() Failure: I don't like this exception", ex.Message);
				Assert.Null(ex.InnerException);
			}

			[Fact]
			public static async Task DerivedExceptionThrown_InspectorThrows()
			{
				static Task testCode() => throw new ArgumentNullException();
				var thrownByInspector = new DivideByZeroException();

				var ex = await Record.ExceptionAsync(() => Assert.ThrowsAnyAsync<ArgumentException>(testCode, _ => throw thrownByInspector));

				Assert.IsType<ThrowsAnyException>(ex);
				Assert.Equal("Assert.ThrowsAny() Failure: Exception thrown by inspector", ex.Message);
				Assert.Same(thrownByInspector, ex.InnerException);
			}

			[Fact]
			public static async Task SkipExceptionEscapes()
			{
				static Task testCode() { Assert.Skip("This is a skipped test"); return Task.CompletedTask; }

				try
				{
					await Assert.ThrowsAnyAsync<Exception>(testCode, _ => null);
					Assert.Fail("The exception should not be caught");
				}
				catch (Exception ex)
				{
					Assert.Equal(DynamicSkipToken.Value + "This is a skipped test", ex.Message);
				}
			}
		}
	}

	public class ThrowsAsync
	{
		public class WithoutInspector
		{
			[Fact]
			public static async Task GuardClause()
			{
				await Assert.ThrowsAsync<ArgumentNullException>("testCode", () => Assert.ThrowsAsync<ArgumentException>(default!));
			}

			[Fact]
			public static async Task NoExceptionThrown()
			{
				static Task testCode() => Task.FromResult(42);

				var ex = await Record.ExceptionAsync(() => Assert.ThrowsAsync<ArgumentException>(testCode));

				Assert.IsType<ThrowsException>(ex);
				Assert.Equal(
					"Assert.Throws() Failure: No exception was thrown" + Environment.NewLine +
					"Expected: typeof(System.ArgumentException)",
					ex.Message
				);
				Assert.Null(ex.InnerException);
			}

			[Fact]
			public static async Task CorrectExceptionThrown()
			{
				static Task testCode() => throw new ArgumentException();

				await Assert.ThrowsAsync<ArgumentException>(testCode);
			}

			[Fact]
			public static async Task IncorrectExceptionThrown()
			{
				var thrown = new DivideByZeroException();
				Task testCode() => throw thrown;

				var ex = await Record.ExceptionAsync(() => Assert.ThrowsAsync<ArgumentException>(testCode));

				Assert.IsType<ThrowsException>(ex);
				Assert.Equal(
					"Assert.Throws() Failure: Exception type was not an exact match" + Environment.NewLine +
					"Expected: typeof(System.ArgumentException)" + Environment.NewLine +
					"Actual:   typeof(System.DivideByZeroException)",
					ex.Message
				);
				Assert.Same(thrown, ex.InnerException);
			}

			[Fact]
			public static async Task DerivedExceptionThrown()
			{
				var thrown = new ArgumentNullException();
				Task testCode() => throw thrown;

				var ex = await Record.ExceptionAsync(() => Assert.ThrowsAsync<ArgumentException>(testCode));

				Assert.IsType<ThrowsException>(ex);
				Assert.Equal(
					"Assert.Throws() Failure: Exception type was not an exact match" + Environment.NewLine +
					"Expected: typeof(System.ArgumentException)" + Environment.NewLine +
					"Actual:   typeof(System.ArgumentNullException)",
					ex.Message
				);
				Assert.Same(thrown, ex.InnerException);
			}

			[Fact]
			public static async Task SkipExceptionEscapes()
			{
				static Task testCode() { Assert.Skip("This is a skipped test"); return Task.CompletedTask; }

				try
				{
					await Assert.ThrowsAsync<Exception>(testCode);
					Assert.Fail("The exception should not be caught");
				}
				catch (Exception ex)
				{
					Assert.Equal(DynamicSkipToken.Value + "This is a skipped test", ex.Message);
				}
			}
		}

		public class WithInspector
		{
			[Fact]
			public static async Task GuardClause()
			{
				await Assert.ThrowsAsync<ArgumentNullException>("testCode", () => Assert.ThrowsAsync<ArgumentException>(default!, _ => null));
			}

			[Fact]
			public static async Task NoExceptionThrown()
			{
				static Task testCode() => Task.FromResult(42);

				var ex = await Record.ExceptionAsync(() => Assert.ThrowsAsync<ArgumentException>(testCode, _ => null));

				Assert.IsType<ThrowsException>(ex);
				Assert.Equal(
					"Assert.Throws() Failure: No exception was thrown" + Environment.NewLine +
					"Expected: typeof(System.ArgumentException)",
					ex.Message
				);
				Assert.Null(ex.InnerException);
			}

			[Fact]
			public static async Task CorrectExceptionThrown_InspectorPasses()
			{
				static Task testCode() => throw new ArgumentException();

				await Assert.ThrowsAsync<ArgumentException>(testCode, _ => null);
			}

			[Fact]
			public static async Task CorrectExceptionThrown_InspectorFails()
			{
				static Task testCode() => throw new ArgumentException();

				var ex = await Record.ExceptionAsync(() => Assert.ThrowsAsync<ArgumentException>(testCode, _ => "I don't like this exception"));

				Assert.IsType<ThrowsException>(ex);
				Assert.Equal("Assert.Throws() Failure: I don't like this exception", ex.Message);
				Assert.Null(ex.InnerException);
			}

			[Fact]
			public static async Task CorrectExceptionThrown_InspectorThrows()
			{
				static Task testCode() => throw new ArgumentException();
				var thrownByInspector = new DivideByZeroException();

				var ex = await Record.ExceptionAsync(() => Assert.ThrowsAsync<ArgumentException>(testCode, _ => throw thrownByInspector));

				Assert.IsType<ThrowsException>(ex);
				Assert.Equal("Assert.Throws() Failure: Exception thrown by inspector", ex.Message);
				Assert.Same(thrownByInspector, ex.InnerException);
			}

			[Fact]
			public static async Task IncorrectExceptionThrown()
			{
				var thrown = new DivideByZeroException();
				Task testCode() => throw thrown;

				var ex = await Record.ExceptionAsync(() => Assert.ThrowsAsync<ArgumentException>(testCode, _ => null));

				Assert.IsType<ThrowsException>(ex);
				Assert.Equal(
					"Assert.Throws() Failure: Exception type was not an exact match" + Environment.NewLine +
					"Expected: typeof(System.ArgumentException)" + Environment.NewLine +
					"Actual:   typeof(System.DivideByZeroException)",
					ex.Message
				);
				Assert.Same(thrown, ex.InnerException);
			}

			[Fact]
			public static async Task DerivedExceptionThrown()
			{
				var thrown = new ArgumentNullException();
				Task testCode() => throw thrown;

				var ex = await Record.ExceptionAsync(() => Assert.ThrowsAsync<ArgumentException>(testCode, _ => null));

				Assert.IsType<ThrowsException>(ex);
				Assert.Equal(
					"Assert.Throws() Failure: Exception type was not an exact match" + Environment.NewLine +
					"Expected: typeof(System.ArgumentException)" + Environment.NewLine +
					"Actual:   typeof(System.ArgumentNullException)",
					ex.Message
				);
				Assert.Same(thrown, ex.InnerException);
			}

			[Fact]
			public static async Task SkipExceptionEscapes()
			{
				static Task testCode() { Assert.Skip("This is a skipped test"); return Task.CompletedTask; }

				try
				{
					await Assert.ThrowsAsync<Exception>(testCode, _ => null);
					Assert.Fail("The exception should not be caught");
				}
				catch (Exception ex)
				{
					Assert.Equal(DynamicSkipToken.Value + "This is a skipped test", ex.Message);
				}
			}
		}
	}

	public class ThrowsAsync_ArgumentException
	{
		[Fact]
		public static async Task GuardClause()
		{
			await Assert.ThrowsAsync<ArgumentNullException>("testCode", () => Assert.ThrowsAsync<ArgumentException>("paramName", default!));
		}

		[Fact]
		public static async Task NoExceptionThrown()
		{
			static Task testCode() => Task.FromResult(42);

			var ex = await Record.ExceptionAsync(() => Assert.ThrowsAsync<ArgumentException>("paramName", testCode));

			Assert.IsType<ThrowsException>(ex);
			Assert.Equal(
				"Assert.Throws() Failure: No exception was thrown" + Environment.NewLine +
				"Expected: typeof(System.ArgumentException)",
				ex.Message
			);
			Assert.Null(ex.InnerException);
		}

		[Fact]
		public static async Task CorrectExceptionThrown()
		{
			static Task testCode() => throw new ArgumentException("Hello world", "paramName");

			await Assert.ThrowsAsync<ArgumentException>("paramName", testCode);
		}

		[Fact]
		public static async Task IncorrectParameterName()
		{
			static Task testCode() => throw new ArgumentException("Hello world", "paramName1");

			var ex = await Record.ExceptionAsync(() => Assert.ThrowsAsync<ArgumentException>("paramName2", testCode));

			Assert.IsType<ThrowsException>(ex);
			Assert.Equal(
				"Assert.Throws() Failure: Incorrect parameter name" + Environment.NewLine +
				"Exception: typeof(System.ArgumentException)" + Environment.NewLine +
				"Expected:  \"paramName2\"" + Environment.NewLine +
				"Actual:    \"paramName1\"",
				ex.Message
			);
		}

		[Fact]
		public static async Task IncorrectExceptionThrown()
		{
			var thrown = new DivideByZeroException();
			Task testCode() => throw thrown;

			var ex = await Record.ExceptionAsync(() => Assert.ThrowsAsync<ArgumentException>("paramName", testCode));

			Assert.IsType<ThrowsException>(ex);
			Assert.Equal(
				"Assert.Throws() Failure: Exception type was not an exact match" + Environment.NewLine +
				"Expected: typeof(System.ArgumentException)" + Environment.NewLine +
				"Actual:   typeof(System.DivideByZeroException)",
				ex.Message
			);
			Assert.Same(thrown, ex.InnerException);
		}

		[Fact]
		public static async Task DerivedExceptionThrown()
		{
			var thrown = new ArgumentNullException();
			Task testCode() => throw thrown;

			var ex = await Record.ExceptionAsync(() => Assert.ThrowsAsync<ArgumentException>("paramName", testCode));

			Assert.IsType<ThrowsException>(ex);
			Assert.Equal(
				"Assert.Throws() Failure: Exception type was not an exact match" + Environment.NewLine +
				"Expected: typeof(System.ArgumentException)" + Environment.NewLine +
				"Actual:   typeof(System.ArgumentNullException)",
				ex.Message
			);
			Assert.Same(thrown, ex.InnerException);
		}
	}
}
